Internal Server Error: /add-to-cart/
Traceback (most recent call last):
  File "/home/tspl/.local/lib/python3.8/site-packages/django/core/handlers/exception.py", line 55, in inner
    response = get_response(request)
  File "/home/tspl/.local/lib/python3.8/site-packages/django/core/handlers/base.py", line 197, in _get_response
    response = wrapped_callback(request, *callback_args, **callback_kwargs)
  File "/home/tspl/Coffeeshop-/app/views.py", line 38, in add_to_cart
    cart_item, created = CartItem.objects.get_or_create(
  File "/home/tspl/.local/lib/python3.8/site-packages/django/db/models/manager.py", line 87, in manager_method
    return getattr(self.get_queryset(), name)(*args, **kwargs)
  File "/home/tspl/.local/lib/python3.8/site-packages/django/db/models/query.py", line 916, in get_or_create
    return self.get(**kwargs), False
  File "/home/tspl/.local/lib/python3.8/site-packages/django/db/models/query.py", line 623, in get
    clone = self._chain() if self.query.combinator else self.filter(*args, **kwargs)
  File "/home/tspl/.local/lib/python3.8/site-packages/django/db/models/query.py", line 1436, in filter
    return self._filter_or_exclude(False, args, kwargs)
  File "/home/tspl/.local/lib/python3.8/site-packages/django/db/models/query.py", line 1454, in _filter_or_exclude
    clone._filter_or_exclude_inplace(negate, args, kwargs)
  File "/home/tspl/.local/lib/python3.8/site-packages/django/db/models/query.py", line 1461, in _filter_or_exclude_inplace
    self._query.add_q(Q(*args, **kwargs))
  File "/home/tspl/.local/lib/python3.8/site-packages/django/db/models/sql/query.py", line 1546, in add_q
    clause, _ = self._add_q(q_object, self.used_aliases)
  File "/home/tspl/.local/lib/python3.8/site-packages/django/db/models/sql/query.py", line 1577, in _add_q
    child_clause, needed_inner = self.build_filter(
  File "/home/tspl/.local/lib/python3.8/site-packages/django/db/models/sql/query.py", line 1427, in build_filter
    lookups, parts, reffed_expression = self.solve_lookup_type(arg, summarize)
  File "/home/tspl/.local/lib/python3.8/site-packages/django/db/models/sql/query.py", line 1237, in solve_lookup_type
    _, field, _, lookup_parts = self.names_to_path(lookup_splitted, self.get_meta())
  File "/home/tspl/.local/lib/python3.8/site-packages/django/db/models/sql/query.py", line 1725, in names_to_path
    raise FieldError(
django.core.exceptions.FieldError: Cannot resolve keyword 'user' into field. Choices are: added_at, id, product, product_id, quantity
"POST /add-to-cart/ HTTP/1.1" 500 123217
Internal Server Error: /add-to-cart/
Traceback (most recent call last):
  File "/home/tspl/.local/lib/python3.8/site-packages/django/core/handlers/exception.py", line 55, in inner
    response = get_response(request)
  File "/home/tspl/.local/lib/python3.8/site-packages/django/core/handlers/base.py", line 197, in _get_response
    response = wrapped_callback(request, *callback_args, **callback_kwargs)
  File "/home/tspl/Coffeeshop-/app/views.py", line 38, in add_to_cart
    cart_item, created = CartItem.objects.get_or_create(
  File "/home/tspl/.local/lib/python3.8/site-packages/django/db/models/manager.py", line 87, in manager_method
    return getattr(self.get_queryset(), name)(*args, **kwargs)
  File "/home/tspl/.local/lib/python3.8/site-packages/django/db/models/query.py", line 916, in get_or_create
    return self.get(**kwargs), False
  File "/home/tspl/.local/lib/python3.8/site-packages/django/db/models/query.py", line 623, in get
    clone = self._chain() if self.query.combinator else self.filter(*args, **kwargs)
  File "/home/tspl/.local/lib/python3.8/site-packages/django/db/models/query.py", line 1436, in filter
    return self._filter_or_exclude(False, args, kwargs)
  File "/home/tspl/.local/lib/python3.8/site-packages/django/db/models/query.py", line 1454, in _filter_or_exclude
    clone._filter_or_exclude_inplace(negate, args, kwargs)
  File "/home/tspl/.local/lib/python3.8/site-packages/django/db/models/query.py", line 1461, in _filter_or_exclude_inplace
    self._query.add_q(Q(*args, **kwargs))
  File "/home/tspl/.local/lib/python3.8/site-packages/django/db/models/sql/query.py", line 1546, in add_q
    clause, _ = self._add_q(q_object, self.used_aliases)
  File "/home/tspl/.local/lib/python3.8/site-packages/django/db/models/sql/query.py", line 1577, in _add_q
    child_clause, needed_inner = self.build_filter(
  File "/home/tspl/.local/lib/python3.8/site-packages/django/db/models/sql/query.py", line 1427, in build_filter
    lookups, parts, reffed_expression = self.solve_lookup_type(arg, summarize)
  File "/home/tspl/.local/lib/python3.8/site-packages/django/db/models/sql/query.py", line 1237, in solve_lookup_type
    _, field, _, lookup_parts = self.names_to_path(lookup_splitted, self.get_meta())
  File "/home/tspl/.local/lib/python3.8/site-packages/django/db/models/sql/query.py", line 1725, in names_to_path
    raise FieldError(
django.core.exceptions.FieldError: Cannot resolve keyword 'user' into field. Choices are: added_at, id, product, product_id, quantity
"POST /add-to-cart/ HTTP/1.1" 500 123348
Internal Server Error: /add-to-cart/
Traceback (most recent call last):
  File "/home/tspl/.local/lib/python3.8/site-packages/django/core/handlers/exception.py", line 55, in inner
    response = get_response(request)
  File "/home/tspl/.local/lib/python3.8/site-packages/django/core/handlers/base.py", line 197, in _get_response
    response = wrapped_callback(request, *callback_args, **callback_kwargs)
  File "/home/tspl/Coffeeshop-/app/views.py", line 38, in add_to_cart
    cart_item, created = CartItem.objects.get_or_create(
  File "/home/tspl/.local/lib/python3.8/site-packages/django/db/models/manager.py", line 87, in manager_method
    return getattr(self.get_queryset(), name)(*args, **kwargs)
  File "/home/tspl/.local/lib/python3.8/site-packages/django/db/models/query.py", line 916, in get_or_create
    return self.get(**kwargs), False
  File "/home/tspl/.local/lib/python3.8/site-packages/django/db/models/query.py", line 623, in get
    clone = self._chain() if self.query.combinator else self.filter(*args, **kwargs)
  File "/home/tspl/.local/lib/python3.8/site-packages/django/db/models/query.py", line 1436, in filter
    return self._filter_or_exclude(False, args, kwargs)
  File "/home/tspl/.local/lib/python3.8/site-packages/django/db/models/query.py", line 1454, in _filter_or_exclude
    clone._filter_or_exclude_inplace(negate, args, kwargs)
  File "/home/tspl/.local/lib/python3.8/site-packages/django/db/models/query.py", line 1461, in _filter_or_exclude_inplace
    self._query.add_q(Q(*args, **kwargs))
  File "/home/tspl/.local/lib/python3.8/site-packages/django/db/models/sql/query.py", line 1546, in add_q
    clause, _ = self._add_q(q_object, self.used_aliases)
  File "/home/tspl/.local/lib/python3.8/site-packages/django/db/models/sql/query.py", line 1577, in _add_q
    child_clause, needed_inner = self.build_filter(
  File "/home/tspl/.local/lib/python3.8/site-packages/django/db/models/sql/query.py", line 1427, in build_filter
    lookups, parts, reffed_expression = self.solve_lookup_type(arg, summarize)
  File "/home/tspl/.local/lib/python3.8/site-packages/django/db/models/sql/query.py", line 1237, in solve_lookup_type
    _, field, _, lookup_parts = self.names_to_path(lookup_splitted, self.get_meta())
  File "/home/tspl/.local/lib/python3.8/site-packages/django/db/models/sql/query.py", line 1725, in names_to_path
    raise FieldError(
django.core.exceptions.FieldError: Cannot resolve keyword 'user' into field. Choices are: added_at, id, product, product_id, quantity
"POST /add-to-cart/ HTTP/1.1" 500 123348
Internal Server Error: /accounts/login/
Traceback (most recent call last):
  File "/home/tspl/.local/lib/python3.8/site-packages/django/core/handlers/exception.py", line 55, in inner
    response = get_response(request)
  File "/home/tspl/.local/lib/python3.8/site-packages/django/core/handlers/base.py", line 220, in _get_response
    response = response.render()
  File "/home/tspl/.local/lib/python3.8/site-packages/django/template/response.py", line 114, in render
    self.content = self.rendered_content
  File "/home/tspl/.local/lib/python3.8/site-packages/django/template/response.py", line 90, in rendered_content
    template = self.resolve_template(self.template_name)
  File "/home/tspl/.local/lib/python3.8/site-packages/django/template/response.py", line 72, in resolve_template
    return select_template(template, using=self.using)
  File "/home/tspl/.local/lib/python3.8/site-packages/django/template/loader.py", line 47, in select_template
    raise TemplateDoesNotExist(", ".join(template_name_list), chain=chain)
django.template.exceptions.TemplateDoesNotExist: registration/login.html
"GET /accounts/login/?next=/add-to-cart/ HTTP/1.1" 500 83530
Internal Server Error: /accounts/login/
Traceback (most recent call last):
  File "/home/tspl/.local/lib/python3.8/site-packages/django/core/handlers/exception.py", line 55, in inner
    response = get_response(request)
  File "/home/tspl/.local/lib/python3.8/site-packages/django/core/handlers/base.py", line 220, in _get_response
    response = response.render()
  File "/home/tspl/.local/lib/python3.8/site-packages/django/template/response.py", line 114, in render
    self.content = self.rendered_content
  File "/home/tspl/.local/lib/python3.8/site-packages/django/template/response.py", line 90, in rendered_content
    template = self.resolve_template(self.template_name)
  File "/home/tspl/.local/lib/python3.8/site-packages/django/template/response.py", line 72, in resolve_template
    return select_template(template, using=self.using)
  File "/home/tspl/.local/lib/python3.8/site-packages/django/template/loader.py", line 47, in select_template
    raise TemplateDoesNotExist(", ".join(template_name_list), chain=chain)
django.template.exceptions.TemplateDoesNotExist: registration/login.html
"GET /accounts/login/?next=/add-to-cart/ HTTP/1.1" 500 83530
Internal Server Error: /accounts/login/
Traceback (most recent call last):
  File "/home/tspl/.local/lib/python3.8/site-packages/django/core/handlers/exception.py", line 55, in inner
    response = get_response(request)
  File "/home/tspl/.local/lib/python3.8/site-packages/django/core/handlers/base.py", line 220, in _get_response
    response = response.render()
  File "/home/tspl/.local/lib/python3.8/site-packages/django/template/response.py", line 114, in render
    self.content = self.rendered_content
  File "/home/tspl/.local/lib/python3.8/site-packages/django/template/response.py", line 90, in rendered_content
    template = self.resolve_template(self.template_name)
  File "/home/tspl/.local/lib/python3.8/site-packages/django/template/response.py", line 72, in resolve_template
    return select_template(template, using=self.using)
  File "/home/tspl/.local/lib/python3.8/site-packages/django/template/loader.py", line 47, in select_template
    raise TemplateDoesNotExist(", ".join(template_name_list), chain=chain)
django.template.exceptions.TemplateDoesNotExist: registration/login.html
"GET /accounts/login/?next=/add-to-cart/ HTTP/1.1" 500 83530
